An error occurred: '71ErpnEY9UQEHzE4zMiwH8Vh3APUocYfB4ZM9aW288Bp'
Traceback (most recent call last):
  File "D:\cryptoEscrow\transaction_checker_at_interval.py", line 46, in execute
    handleResponse(response, bot_state, bot)
  File "D:\cryptoEscrow\transaction_checker_at_interval.py", line 110, in handleResponse
    proceed_transaction(bot_state, wallet['tradeId'], response, tradeDetails, bot)
  File "D:\cryptoEscrow\transaction_checker_at_interval.py", line 154, in proceed_transaction
    wallet = bot_state.get_address_info(response['publicKey'])
  File "D:\cryptoEscrow\globalState.py", line 170, in get_address_info
    return self.state["wallet_checker_queue"][publicKey]
KeyError: '71ErpnEY9UQEHzE4zMiwH8Vh3APUocYfB4ZM9aW288Bp'

An error occurred: 'totalPrice'
Traceback (most recent call last):
  File "D:\cryptoEscrow\transaction_checker_at_interval.py", line 46, in execute
    handleResponse(response, bot_state, bot)
  File "D:\cryptoEscrow\transaction_checker_at_interval.py", line 110, in handleResponse
    proceed_transaction(bot_state, wallet['tradeId'], response, tradeDetails, bot)
  File "D:\cryptoEscrow\transaction_checker_at_interval.py", line 170, in proceed_transaction
    text=f"Tx ID: `{tradeId}`\nItem: {item_details['title']}\nSeller: {item_details['seller']}\nFinal Amount: {tradeDetails['totalPrice']}\nDelivery Mode: {item_details['type']}\nInvoice Status: Paid\n",
KeyError: 'totalPrice'

An error occurred: add_timeout() missing 1 required positional argument: 'cmd'
Traceback (most recent call last):
  File "D:\cryptoEscrow\transaction_checker_at_interval.py", line 46, in execute
    handleResponse(response, bot_state, bot)
  File "D:\cryptoEscrow\transaction_checker_at_interval.py", line 110, in handleResponse
    proceed_transaction(bot_state, wallet['tradeId'], response, tradeDetails, bot)
  File "D:\cryptoEscrow\transaction_checker_at_interval.py", line 196, in proceed_transaction
    t = bot_state.add_timeout(10*60, tradeId)
TypeError: add_timeout() missing 1 required positional argument: 'cmd'

An error occurred: Message is not modified: specified new message content and reply markup are exactly the same as a current content and reply markup of the message
Traceback (most recent call last):
  File "D:\cryptoEscrow\transaction_checker_at_interval.py", line 46, in execute
    handleResponse(response, bot_state, bot)
  File "D:\cryptoEscrow\transaction_checker_at_interval.py", line 110, in handleResponse
    proceed_transaction(bot_state, wallet['tradeId'], response, tradeDetails, bot)
  File "D:\cryptoEscrow\transaction_checker_at_interval.py", line 168, in proceed_transaction
    message = bot.edit_message_text(
  File "C:\Users\DV\AppData\Local\Programs\Python\Python39\lib\site-packages\telegram\bot.py", line 130, in decorator
    result = func(*args, **kwargs)
  File "C:\Users\DV\AppData\Local\Programs\Python\Python39\lib\site-packages\telegram\bot.py", line 2582, in edit_message_text
    return self._message(
  File "C:\Users\DV\AppData\Local\Programs\Python\Python39\lib\site-packages\telegram\ext\extbot.py", line 199, in _message
    result = super()._message(
  File "C:\Users\DV\AppData\Local\Programs\Python\Python39\lib\site-packages\telegram\bot.py", line 332, in _message
    result = self._post(endpoint, data, timeout=timeout, api_kwargs=api_kwargs)
  File "C:\Users\DV\AppData\Local\Programs\Python\Python39\lib\site-packages\telegram\bot.py", line 295, in _post
    return self.request.post(
  File "C:\Users\DV\AppData\Local\Programs\Python\Python39\lib\site-packages\telegram\utils\request.py", line 356, in post
    result = self._request_wrapper(
  File "C:\Users\DV\AppData\Local\Programs\Python\Python39\lib\site-packages\telegram\utils\request.py", line 279, in _request_wrapper
    raise BadRequest(message)
telegram.error.BadRequest: Message is not modified: specified new message content and reply markup are exactly the same as a current content and reply markup of the message

An error occurred: Message is not modified: specified new message content and reply markup are exactly the same as a current content and reply markup of the message
Traceback (most recent call last):
  File "D:\cryptoEscrow\transaction_checker_at_interval.py", line 46, in execute
    handleResponse(response, bot_state, bot)
  File "D:\cryptoEscrow\transaction_checker_at_interval.py", line 110, in handleResponse
    proceed_transaction(bot_state, wallet['tradeId'], response, tradeDetails, bot)
  File "D:\cryptoEscrow\transaction_checker_at_interval.py", line 168, in proceed_transaction
    message = bot.edit_message_text(
  File "C:\Users\DV\AppData\Local\Programs\Python\Python39\lib\site-packages\telegram\bot.py", line 130, in decorator
    result = func(*args, **kwargs)
  File "C:\Users\DV\AppData\Local\Programs\Python\Python39\lib\site-packages\telegram\bot.py", line 2582, in edit_message_text
    return self._message(
  File "C:\Users\DV\AppData\Local\Programs\Python\Python39\lib\site-packages\telegram\ext\extbot.py", line 199, in _message
    result = super()._message(
  File "C:\Users\DV\AppData\Local\Programs\Python\Python39\lib\site-packages\telegram\bot.py", line 332, in _message
    result = self._post(endpoint, data, timeout=timeout, api_kwargs=api_kwargs)
  File "C:\Users\DV\AppData\Local\Programs\Python\Python39\lib\site-packages\telegram\bot.py", line 295, in _post
    return self.request.post(
  File "C:\Users\DV\AppData\Local\Programs\Python\Python39\lib\site-packages\telegram\utils\request.py", line 356, in post
    result = self._request_wrapper(
  File "C:\Users\DV\AppData\Local\Programs\Python\Python39\lib\site-packages\telegram\utils\request.py", line 279, in _request_wrapper
    raise BadRequest(message)
telegram.error.BadRequest: Message is not modified: specified new message content and reply markup are exactly the same as a current content and reply markup of the message

An error occurred: add_timeout() missing 1 required positional argument: 'cmd'
Traceback (most recent call last):
  File "D:\cryptoEscrow\transaction_checker_at_interval.py", line 46, in execute
    handleResponse(response, bot_state, bot)
  File "D:\cryptoEscrow\transaction_checker_at_interval.py", line 110, in handleResponse
    proceed_transaction(bot_state, wallet['tradeId'], response, tradeDetails, bot)
  File "D:\cryptoEscrow\transaction_checker_at_interval.py", line 196, in proceed_transaction
    t = bot_state.add_timeout(10*60, tradeId)
TypeError: add_timeout() missing 1 required positional argument: 'cmd'

An error occurred: Message is not modified: specified new message content and reply markup are exactly the same as a current content and reply markup of the message
Traceback (most recent call last):
  File "D:\cryptoEscrow\transaction_checker_at_interval.py", line 46, in execute
    handleResponse(response, bot_state, bot)
  File "D:\cryptoEscrow\transaction_checker_at_interval.py", line 110, in handleResponse
    proceed_transaction(bot_state, wallet['tradeId'], response, tradeDetails, bot)
  File "D:\cryptoEscrow\transaction_checker_at_interval.py", line 168, in proceed_transaction
    message = bot.edit_message_text(
  File "C:\Users\DV\AppData\Local\Programs\Python\Python39\lib\site-packages\telegram\bot.py", line 130, in decorator
    result = func(*args, **kwargs)
  File "C:\Users\DV\AppData\Local\Programs\Python\Python39\lib\site-packages\telegram\bot.py", line 2582, in edit_message_text
    return self._message(
  File "C:\Users\DV\AppData\Local\Programs\Python\Python39\lib\site-packages\telegram\ext\extbot.py", line 199, in _message
    result = super()._message(
  File "C:\Users\DV\AppData\Local\Programs\Python\Python39\lib\site-packages\telegram\bot.py", line 332, in _message
    result = self._post(endpoint, data, timeout=timeout, api_kwargs=api_kwargs)
  File "C:\Users\DV\AppData\Local\Programs\Python\Python39\lib\site-packages\telegram\bot.py", line 295, in _post
    return self.request.post(
  File "C:\Users\DV\AppData\Local\Programs\Python\Python39\lib\site-packages\telegram\utils\request.py", line 356, in post
    result = self._request_wrapper(
  File "C:\Users\DV\AppData\Local\Programs\Python\Python39\lib\site-packages\telegram\utils\request.py", line 279, in _request_wrapper
    raise BadRequest(message)
telegram.error.BadRequest: Message is not modified: specified new message content and reply markup are exactly the same as a current content and reply markup of the message

An error occurred: Chat not found
Traceback (most recent call last):
  File "D:\cryptoEscrow\transaction_checker_at_interval.py", line 46, in execute
    handleResponse(response, bot_state, bot)
  File "D:\cryptoEscrow\transaction_checker_at_interval.py", line 109, in handleResponse
    proceed_transaction(bot_state, wallet['tradeId'], response, tradeDetails, bot)
  File "D:\cryptoEscrow\transaction_checker_at_interval.py", line 155, in proceed_transaction
    bot.send_message(chat_id=tradeDetails["buyer"], text="Your Transaction is now confirmed in Blockchain, seller is now notified to send your product")
  File "C:\Users\DV\AppData\Local\Programs\Python\Python39\lib\site-packages\telegram\bot.py", line 130, in decorator
    result = func(*args, **kwargs)
  File "C:\Users\DV\AppData\Local\Programs\Python\Python39\lib\site-packages\telegram\bot.py", line 513, in send_message
    return self._message(  # type: ignore[return-value]
  File "C:\Users\DV\AppData\Local\Programs\Python\Python39\lib\site-packages\telegram\ext\extbot.py", line 199, in _message
    result = super()._message(
  File "C:\Users\DV\AppData\Local\Programs\Python\Python39\lib\site-packages\telegram\bot.py", line 332, in _message
    result = self._post(endpoint, data, timeout=timeout, api_kwargs=api_kwargs)
  File "C:\Users\DV\AppData\Local\Programs\Python\Python39\lib\site-packages\telegram\bot.py", line 295, in _post
    return self.request.post(
  File "C:\Users\DV\AppData\Local\Programs\Python\Python39\lib\site-packages\telegram\utils\request.py", line 356, in post
    result = self._request_wrapper(
  File "C:\Users\DV\AppData\Local\Programs\Python\Python39\lib\site-packages\telegram\utils\request.py", line 279, in _request_wrapper
    raise BadRequest(message)
telegram.error.BadRequest: Chat not found

An error occurred: Chat not found
Traceback (most recent call last):
  File "D:\cryptoEscrow\transaction_checker_at_interval.py", line 46, in execute
    handleResponse(response, bot_state, bot)
  File "D:\cryptoEscrow\transaction_checker_at_interval.py", line 109, in handleResponse
    proceed_transaction(bot_state, wallet['tradeId'], response, tradeDetails, bot)
  File "D:\cryptoEscrow\transaction_checker_at_interval.py", line 155, in proceed_transaction
    bot.send_message(chat_id=tradeDetails["buyer"], text="Your Transaction is now confirmed in Blockchain, seller is now notified to send your product")
  File "C:\Users\DV\AppData\Local\Programs\Python\Python39\lib\site-packages\telegram\bot.py", line 130, in decorator
    result = func(*args, **kwargs)
  File "C:\Users\DV\AppData\Local\Programs\Python\Python39\lib\site-packages\telegram\bot.py", line 513, in send_message
    return self._message(  # type: ignore[return-value]
  File "C:\Users\DV\AppData\Local\Programs\Python\Python39\lib\site-packages\telegram\ext\extbot.py", line 199, in _message
    result = super()._message(
  File "C:\Users\DV\AppData\Local\Programs\Python\Python39\lib\site-packages\telegram\bot.py", line 332, in _message
    result = self._post(endpoint, data, timeout=timeout, api_kwargs=api_kwargs)
  File "C:\Users\DV\AppData\Local\Programs\Python\Python39\lib\site-packages\telegram\bot.py", line 295, in _post
    return self.request.post(
  File "C:\Users\DV\AppData\Local\Programs\Python\Python39\lib\site-packages\telegram\utils\request.py", line 356, in post
    result = self._request_wrapper(
  File "C:\Users\DV\AppData\Local\Programs\Python\Python39\lib\site-packages\telegram\utils\request.py", line 279, in _request_wrapper
    raise BadRequest(message)
telegram.error.BadRequest: Chat not found

An error occurred: (pymysql.err.InternalError) Packet sequence number wrong - got 1 expected 2
(Background on this error at: https://sqlalche.me/e/20/2j85)
Traceback (most recent call last):
  File "C:\Users\DV\AppData\Local\Programs\Python\Python39\lib\site-packages\sqlalchemy\engine\base.py", line 146, in __init__
    self._dbapi_connection = engine.raw_connection()
  File "C:\Users\DV\AppData\Local\Programs\Python\Python39\lib\site-packages\sqlalchemy\engine\base.py", line 3302, in raw_connection
    return self.pool.connect()
  File "C:\Users\DV\AppData\Local\Programs\Python\Python39\lib\site-packages\sqlalchemy\pool\base.py", line 449, in connect
    return _ConnectionFairy._checkout(self)
  File "C:\Users\DV\AppData\Local\Programs\Python\Python39\lib\site-packages\sqlalchemy\pool\base.py", line 1263, in _checkout
    fairy = _ConnectionRecord.checkout(pool)
  File "C:\Users\DV\AppData\Local\Programs\Python\Python39\lib\site-packages\sqlalchemy\pool\base.py", line 712, in checkout
    rec = pool._do_get()
  File "C:\Users\DV\AppData\Local\Programs\Python\Python39\lib\site-packages\sqlalchemy\pool\impl.py", line 180, in _do_get
    self._dec_overflow()
  File "C:\Users\DV\AppData\Local\Programs\Python\Python39\lib\site-packages\sqlalchemy\util\langhelpers.py", line 146, in __exit__
    raise exc_value.with_traceback(exc_tb)
  File "C:\Users\DV\AppData\Local\Programs\Python\Python39\lib\site-packages\sqlalchemy\pool\impl.py", line 177, in _do_get
    return self._create_connection()
  File "C:\Users\DV\AppData\Local\Programs\Python\Python39\lib\site-packages\sqlalchemy\pool\base.py", line 390, in _create_connection
    return _ConnectionRecord(self)
  File "C:\Users\DV\AppData\Local\Programs\Python\Python39\lib\site-packages\sqlalchemy\pool\base.py", line 674, in __init__
    self.__connect()
  File "C:\Users\DV\AppData\Local\Programs\Python\Python39\lib\site-packages\sqlalchemy\pool\base.py", line 901, in __connect
    pool.logger.debug("Error on connect(): %s", e)
  File "C:\Users\DV\AppData\Local\Programs\Python\Python39\lib\site-packages\sqlalchemy\util\langhelpers.py", line 146, in __exit__
    raise exc_value.with_traceback(exc_tb)
  File "C:\Users\DV\AppData\Local\Programs\Python\Python39\lib\site-packages\sqlalchemy\pool\base.py", line 896, in __connect
    self.dbapi_connection = connection = pool._invoke_creator(self)
  File "C:\Users\DV\AppData\Local\Programs\Python\Python39\lib\site-packages\sqlalchemy\engine\create.py", line 643, in connect
    return dialect.connect(*cargs, **cparams)
  File "C:\Users\DV\AppData\Local\Programs\Python\Python39\lib\site-packages\sqlalchemy\engine\default.py", line 621, in connect
    return self.loaded_dbapi.connect(*cargs, **cparams)
  File "C:\Users\DV\AppData\Local\Programs\Python\Python39\lib\site-packages\pymysql\connections.py", line 361, in __init__
    self.connect()
  File "C:\Users\DV\AppData\Local\Programs\Python\Python39\lib\site-packages\pymysql\connections.py", line 669, in connect
    self._request_authentication()
  File "C:\Users\DV\AppData\Local\Programs\Python\Python39\lib\site-packages\pymysql\connections.py", line 957, in _request_authentication
    auth_packet = self._read_packet()
  File "C:\Users\DV\AppData\Local\Programs\Python\Python39\lib\site-packages\pymysql\connections.py", line 757, in _read_packet
    raise err.InternalError(
pymysql.err.InternalError: Packet sequence number wrong - got 1 expected 2

The above exception was the direct cause of the following exception:

Traceback (most recent call last):
  File "D:\cryptoEscrow\transaction_checker_at_interval.py", line 22, in execute
    for key, value in bot_state.get_all_queue_addresses().items():
  File "D:\cryptoEscrow\globalState.py", line 170, in get_all_queue_addresses
    self.state["wallet_checker_queue"] = self.database.fetch_all_wallet_checker_queue()
  File "D:\cryptoEscrow\databaseClass.py", line 65, in fetch_all_wallet_checker_queue
    return self._fetch_all("wallet_checker_queue")
  File "D:\cryptoEscrow\databaseClass.py", line 91, in _fetch_all
    results = self._execute_with_retries(query).fetchall()
  File "D:\cryptoEscrow\databaseClass.py", line 25, in _execute_with_retries
    result = session.execute(text(query))
  File "C:\Users\DV\AppData\Local\Programs\Python\Python39\lib\site-packages\sqlalchemy\orm\session.py", line 2362, in execute
    return self._execute_internal(
  File "C:\Users\DV\AppData\Local\Programs\Python\Python39\lib\site-packages\sqlalchemy\orm\session.py", line 2237, in _execute_internal
    conn = self._connection_for_bind(bind)
  File "C:\Users\DV\AppData\Local\Programs\Python\Python39\lib\site-packages\sqlalchemy\orm\session.py", line 2106, in _connection_for_bind
    return trans._connection_for_bind(engine, execution_options)
  File "<string>", line 2, in _connection_for_bind
  File "C:\Users\DV\AppData\Local\Programs\Python\Python39\lib\site-packages\sqlalchemy\orm\state_changes.py", line 139, in _go
    ret_value = fn(self, *arg, **kw)
  File "C:\Users\DV\AppData\Local\Programs\Python\Python39\lib\site-packages\sqlalchemy\orm\session.py", line 1189, in _connection_for_bind
    conn = bind.connect()
  File "C:\Users\DV\AppData\Local\Programs\Python\Python39\lib\site-packages\sqlalchemy\engine\base.py", line 3278, in connect
    return self._connection_cls(self)
  File "C:\Users\DV\AppData\Local\Programs\Python\Python39\lib\site-packages\sqlalchemy\engine\base.py", line 148, in __init__
    Connection._handle_dbapi_exception_noconnection(
  File "C:\Users\DV\AppData\Local\Programs\Python\Python39\lib\site-packages\sqlalchemy\engine\base.py", line 2442, in _handle_dbapi_exception_noconnection
    raise sqlalchemy_exception.with_traceback(exc_info[2]) from e
  File "C:\Users\DV\AppData\Local\Programs\Python\Python39\lib\site-packages\sqlalchemy\engine\base.py", line 146, in __init__
    self._dbapi_connection = engine.raw_connection()
  File "C:\Users\DV\AppData\Local\Programs\Python\Python39\lib\site-packages\sqlalchemy\engine\base.py", line 3302, in raw_connection
    return self.pool.connect()
  File "C:\Users\DV\AppData\Local\Programs\Python\Python39\lib\site-packages\sqlalchemy\pool\base.py", line 449, in connect
    return _ConnectionFairy._checkout(self)
  File "C:\Users\DV\AppData\Local\Programs\Python\Python39\lib\site-packages\sqlalchemy\pool\base.py", line 1263, in _checkout
    fairy = _ConnectionRecord.checkout(pool)
  File "C:\Users\DV\AppData\Local\Programs\Python\Python39\lib\site-packages\sqlalchemy\pool\base.py", line 712, in checkout
    rec = pool._do_get()
  File "C:\Users\DV\AppData\Local\Programs\Python\Python39\lib\site-packages\sqlalchemy\pool\impl.py", line 180, in _do_get
    self._dec_overflow()
  File "C:\Users\DV\AppData\Local\Programs\Python\Python39\lib\site-packages\sqlalchemy\util\langhelpers.py", line 146, in __exit__
    raise exc_value.with_traceback(exc_tb)
  File "C:\Users\DV\AppData\Local\Programs\Python\Python39\lib\site-packages\sqlalchemy\pool\impl.py", line 177, in _do_get
    return self._create_connection()
  File "C:\Users\DV\AppData\Local\Programs\Python\Python39\lib\site-packages\sqlalchemy\pool\base.py", line 390, in _create_connection
    return _ConnectionRecord(self)
  File "C:\Users\DV\AppData\Local\Programs\Python\Python39\lib\site-packages\sqlalchemy\pool\base.py", line 674, in __init__
    self.__connect()
  File "C:\Users\DV\AppData\Local\Programs\Python\Python39\lib\site-packages\sqlalchemy\pool\base.py", line 901, in __connect
    pool.logger.debug("Error on connect(): %s", e)
  File "C:\Users\DV\AppData\Local\Programs\Python\Python39\lib\site-packages\sqlalchemy\util\langhelpers.py", line 146, in __exit__
    raise exc_value.with_traceback(exc_tb)
  File "C:\Users\DV\AppData\Local\Programs\Python\Python39\lib\site-packages\sqlalchemy\pool\base.py", line 896, in __connect
    self.dbapi_connection = connection = pool._invoke_creator(self)
  File "C:\Users\DV\AppData\Local\Programs\Python\Python39\lib\site-packages\sqlalchemy\engine\create.py", line 643, in connect
    return dialect.connect(*cargs, **cparams)
  File "C:\Users\DV\AppData\Local\Programs\Python\Python39\lib\site-packages\sqlalchemy\engine\default.py", line 621, in connect
    return self.loaded_dbapi.connect(*cargs, **cparams)
  File "C:\Users\DV\AppData\Local\Programs\Python\Python39\lib\site-packages\pymysql\connections.py", line 361, in __init__
    self.connect()
  File "C:\Users\DV\AppData\Local\Programs\Python\Python39\lib\site-packages\pymysql\connections.py", line 669, in connect
    self._request_authentication()
  File "C:\Users\DV\AppData\Local\Programs\Python\Python39\lib\site-packages\pymysql\connections.py", line 957, in _request_authentication
    auth_packet = self._read_packet()
  File "C:\Users\DV\AppData\Local\Programs\Python\Python39\lib\site-packages\pymysql\connections.py", line 757, in _read_packet
    raise err.InternalError(
sqlalchemy.exc.InternalError: (pymysql.err.InternalError) Packet sequence number wrong - got 1 expected 2
(Background on this error at: https://sqlalche.me/e/20/2j85)

An error occurred: 'str' object has no attribute 'message_id'
Traceback (most recent call last):
  File "D:\cryptoEscrow\transaction_checker_at_interval.py", line 45, in execute
    handleResponse(response, bot_state, bot)
  File "D:\cryptoEscrow\transaction_checker_at_interval.py", line 108, in handleResponse
    proceed_transaction(bot_state, wallet['tradeId'], response, tradeDetails, bot)
  File "D:\cryptoEscrow\transaction_checker_at_interval.py", line 191, in proceed_transaction
    bot_state.set_waiting_for_input(tradeDetails["buyer"], "none", 'button')
  File "D:\cryptoEscrow\globalState.py", line 109, in set_waiting_for_input
    'message_id': context[0].message_id,
AttributeError: 'str' object has no attribute 'message_id'

An error occurred: Message is not modified: specified new message content and reply markup are exactly the same as a current content and reply markup of the message
Traceback (most recent call last):
  File "D:\cryptoEscrow\transaction_checker_at_interval.py", line 45, in execute
    handleResponse(response, bot_state, bot)
  File "D:\cryptoEscrow\transaction_checker_at_interval.py", line 108, in handleResponse
    proceed_transaction(bot_state, wallet['tradeId'], response, tradeDetails, bot)
  File "D:\cryptoEscrow\transaction_checker_at_interval.py", line 168, in proceed_transaction
    message = bot.edit_message_text(
  File "C:\Users\DV\AppData\Local\Programs\Python\Python39\lib\site-packages\telegram\bot.py", line 130, in decorator
    result = func(*args, **kwargs)
  File "C:\Users\DV\AppData\Local\Programs\Python\Python39\lib\site-packages\telegram\bot.py", line 2582, in edit_message_text
    return self._message(
  File "C:\Users\DV\AppData\Local\Programs\Python\Python39\lib\site-packages\telegram\ext\extbot.py", line 199, in _message
    result = super()._message(
  File "C:\Users\DV\AppData\Local\Programs\Python\Python39\lib\site-packages\telegram\bot.py", line 332, in _message
    result = self._post(endpoint, data, timeout=timeout, api_kwargs=api_kwargs)
  File "C:\Users\DV\AppData\Local\Programs\Python\Python39\lib\site-packages\telegram\bot.py", line 295, in _post
    return self.request.post(
  File "C:\Users\DV\AppData\Local\Programs\Python\Python39\lib\site-packages\telegram\utils\request.py", line 356, in post
    result = self._request_wrapper(
  File "C:\Users\DV\AppData\Local\Programs\Python\Python39\lib\site-packages\telegram\utils\request.py", line 279, in _request_wrapper
    raise BadRequest(message)
telegram.error.BadRequest: Message is not modified: specified new message content and reply markup are exactly the same as a current content and reply markup of the message

An error occurred: Message is not modified: specified new message content and reply markup are exactly the same as a current content and reply markup of the message
Traceback (most recent call last):
  File "D:\cryptoEscrow\transaction_checker_at_interval.py", line 45, in execute
    handleResponse(response, bot_state, bot)
  File "D:\cryptoEscrow\transaction_checker_at_interval.py", line 108, in handleResponse
    proceed_transaction(bot_state, wallet['tradeId'], response, tradeDetails, bot)
  File "D:\cryptoEscrow\transaction_checker_at_interval.py", line 168, in proceed_transaction
    message = bot.edit_message_text(
  File "C:\Users\DV\AppData\Local\Programs\Python\Python39\lib\site-packages\telegram\bot.py", line 130, in decorator
    result = func(*args, **kwargs)
  File "C:\Users\DV\AppData\Local\Programs\Python\Python39\lib\site-packages\telegram\bot.py", line 2582, in edit_message_text
    return self._message(
  File "C:\Users\DV\AppData\Local\Programs\Python\Python39\lib\site-packages\telegram\ext\extbot.py", line 199, in _message
    result = super()._message(
  File "C:\Users\DV\AppData\Local\Programs\Python\Python39\lib\site-packages\telegram\bot.py", line 332, in _message
    result = self._post(endpoint, data, timeout=timeout, api_kwargs=api_kwargs)
  File "C:\Users\DV\AppData\Local\Programs\Python\Python39\lib\site-packages\telegram\bot.py", line 295, in _post
    return self.request.post(
  File "C:\Users\DV\AppData\Local\Programs\Python\Python39\lib\site-packages\telegram\utils\request.py", line 356, in post
    result = self._request_wrapper(
  File "C:\Users\DV\AppData\Local\Programs\Python\Python39\lib\site-packages\telegram\utils\request.py", line 279, in _request_wrapper
    raise BadRequest(message)
telegram.error.BadRequest: Message is not modified: specified new message content and reply markup are exactly the same as a current content and reply markup of the message

An error occurred: Message is not modified: specified new message content and reply markup are exactly the same as a current content and reply markup of the message
Traceback (most recent call last):
  File "D:\cryptoEscrow\transaction_checker_at_interval.py", line 45, in execute
    handleResponse(response, bot_state, bot)
  File "D:\cryptoEscrow\transaction_checker_at_interval.py", line 108, in handleResponse
    proceed_transaction(bot_state, wallet['tradeId'], response, tradeDetails, bot)
  File "D:\cryptoEscrow\transaction_checker_at_interval.py", line 168, in proceed_transaction
    message = bot.edit_message_text(
  File "C:\Users\DV\AppData\Local\Programs\Python\Python39\lib\site-packages\telegram\bot.py", line 130, in decorator
    result = func(*args, **kwargs)
  File "C:\Users\DV\AppData\Local\Programs\Python\Python39\lib\site-packages\telegram\bot.py", line 2582, in edit_message_text
    return self._message(
  File "C:\Users\DV\AppData\Local\Programs\Python\Python39\lib\site-packages\telegram\ext\extbot.py", line 199, in _message
    result = super()._message(
  File "C:\Users\DV\AppData\Local\Programs\Python\Python39\lib\site-packages\telegram\bot.py", line 332, in _message
    result = self._post(endpoint, data, timeout=timeout, api_kwargs=api_kwargs)
  File "C:\Users\DV\AppData\Local\Programs\Python\Python39\lib\site-packages\telegram\bot.py", line 295, in _post
    return self.request.post(
  File "C:\Users\DV\AppData\Local\Programs\Python\Python39\lib\site-packages\telegram\utils\request.py", line 356, in post
    result = self._request_wrapper(
  File "C:\Users\DV\AppData\Local\Programs\Python\Python39\lib\site-packages\telegram\utils\request.py", line 279, in _request_wrapper
    raise BadRequest(message)
telegram.error.BadRequest: Message is not modified: specified new message content and reply markup are exactly the same as a current content and reply markup of the message

An error occurred: Message is not modified: specified new message content and reply markup are exactly the same as a current content and reply markup of the message
Traceback (most recent call last):
  File "D:\cryptoEscrow\transaction_checker_at_interval.py", line 45, in execute
    handleResponse(response, bot_state, bot)
  File "D:\cryptoEscrow\transaction_checker_at_interval.py", line 108, in handleResponse
    proceed_transaction(bot_state, wallet['tradeId'], response, tradeDetails, bot)
  File "D:\cryptoEscrow\transaction_checker_at_interval.py", line 168, in proceed_transaction
    message = bot.edit_message_text(
  File "C:\Users\DV\AppData\Local\Programs\Python\Python39\lib\site-packages\telegram\bot.py", line 130, in decorator
    result = func(*args, **kwargs)
  File "C:\Users\DV\AppData\Local\Programs\Python\Python39\lib\site-packages\telegram\bot.py", line 2582, in edit_message_text
    return self._message(
  File "C:\Users\DV\AppData\Local\Programs\Python\Python39\lib\site-packages\telegram\ext\extbot.py", line 199, in _message
    result = super()._message(
  File "C:\Users\DV\AppData\Local\Programs\Python\Python39\lib\site-packages\telegram\bot.py", line 332, in _message
    result = self._post(endpoint, data, timeout=timeout, api_kwargs=api_kwargs)
  File "C:\Users\DV\AppData\Local\Programs\Python\Python39\lib\site-packages\telegram\bot.py", line 295, in _post
    return self.request.post(
  File "C:\Users\DV\AppData\Local\Programs\Python\Python39\lib\site-packages\telegram\utils\request.py", line 356, in post
    result = self._request_wrapper(
  File "C:\Users\DV\AppData\Local\Programs\Python\Python39\lib\site-packages\telegram\utils\request.py", line 279, in _request_wrapper
    raise BadRequest(message)
telegram.error.BadRequest: Message is not modified: specified new message content and reply markup are exactly the same as a current content and reply markup of the message

An error occurred: Message is not modified: specified new message content and reply markup are exactly the same as a current content and reply markup of the message
Traceback (most recent call last):
  File "D:\cryptoEscrow\transaction_checker_at_interval.py", line 45, in execute
    handleResponse(response, bot_state, bot)
  File "D:\cryptoEscrow\transaction_checker_at_interval.py", line 108, in handleResponse
    proceed_transaction(bot_state, wallet['tradeId'], response, tradeDetails, bot)
  File "D:\cryptoEscrow\transaction_checker_at_interval.py", line 168, in proceed_transaction
    message = bot.edit_message_text(
  File "C:\Users\DV\AppData\Local\Programs\Python\Python39\lib\site-packages\telegram\bot.py", line 130, in decorator
    result = func(*args, **kwargs)
  File "C:\Users\DV\AppData\Local\Programs\Python\Python39\lib\site-packages\telegram\bot.py", line 2582, in edit_message_text
    return self._message(
  File "C:\Users\DV\AppData\Local\Programs\Python\Python39\lib\site-packages\telegram\ext\extbot.py", line 199, in _message
    result = super()._message(
  File "C:\Users\DV\AppData\Local\Programs\Python\Python39\lib\site-packages\telegram\bot.py", line 332, in _message
    result = self._post(endpoint, data, timeout=timeout, api_kwargs=api_kwargs)
  File "C:\Users\DV\AppData\Local\Programs\Python\Python39\lib\site-packages\telegram\bot.py", line 295, in _post
    return self.request.post(
  File "C:\Users\DV\AppData\Local\Programs\Python\Python39\lib\site-packages\telegram\utils\request.py", line 356, in post
    result = self._request_wrapper(
  File "C:\Users\DV\AppData\Local\Programs\Python\Python39\lib\site-packages\telegram\utils\request.py", line 279, in _request_wrapper
    raise BadRequest(message)
telegram.error.BadRequest: Message is not modified: specified new message content and reply markup are exactly the same as a current content and reply markup of the message

An error occurred: Message is not modified: specified new message content and reply markup are exactly the same as a current content and reply markup of the message
Traceback (most recent call last):
  File "D:\cryptoEscrow\transaction_checker_at_interval.py", line 45, in execute
    handleResponse(response, bot_state, bot)
  File "D:\cryptoEscrow\transaction_checker_at_interval.py", line 108, in handleResponse
    proceed_transaction(bot_state, wallet['tradeId'], response, tradeDetails, bot)
  File "D:\cryptoEscrow\transaction_checker_at_interval.py", line 168, in proceed_transaction
    message = bot.edit_message_text(
  File "C:\Users\DV\AppData\Local\Programs\Python\Python39\lib\site-packages\telegram\bot.py", line 130, in decorator
    result = func(*args, **kwargs)
  File "C:\Users\DV\AppData\Local\Programs\Python\Python39\lib\site-packages\telegram\bot.py", line 2582, in edit_message_text
    return self._message(
  File "C:\Users\DV\AppData\Local\Programs\Python\Python39\lib\site-packages\telegram\ext\extbot.py", line 199, in _message
    result = super()._message(
  File "C:\Users\DV\AppData\Local\Programs\Python\Python39\lib\site-packages\telegram\bot.py", line 332, in _message
    result = self._post(endpoint, data, timeout=timeout, api_kwargs=api_kwargs)
  File "C:\Users\DV\AppData\Local\Programs\Python\Python39\lib\site-packages\telegram\bot.py", line 295, in _post
    return self.request.post(
  File "C:\Users\DV\AppData\Local\Programs\Python\Python39\lib\site-packages\telegram\utils\request.py", line 356, in post
    result = self._request_wrapper(
  File "C:\Users\DV\AppData\Local\Programs\Python\Python39\lib\site-packages\telegram\utils\request.py", line 279, in _request_wrapper
    raise BadRequest(message)
telegram.error.BadRequest: Message is not modified: specified new message content and reply markup are exactly the same as a current content and reply markup of the message

An error occurred: 'float' object is not subscriptable
Traceback (most recent call last):
  File "D:\cryptoEscrow\transaction_checker_at_interval.py", line 46, in execute
    handleResponse(response, bot_state, bot)
  File "D:\cryptoEscrow\transaction_checker_at_interval.py", line 115, in handleResponse
    proceed_transaction(bot_state, wallet['tradeId'], response["amount"], tradeDetails, bot)
  File "D:\cryptoEscrow\transaction_checker_at_interval.py", line 148, in proceed_transaction
    wallet = bot_state.get_address_info(response['publicKey'])
TypeError: 'float' object is not subscriptable

